<?xml version="1.0"?>
<robot name="holoruch_pantilt">
  <link name="base_link">
    <visual>
      <geometry>
        <box size="0.15 0.13 0.01" />
      </geometry>
    </visual>
    <collision>
      <geometry>
        <box size="0.15 0.13 0.01" />
      </geometry>
    </collision>
    <inertial>
      <origin rpy="0 0 0" xyz="0 0 0"/>
      <mass value="0.1"/>
      <inertia ixx="1" ixy="0" ixz="0" iyy="1" iyz="0" izz="1"/>
    </inertial>
  </link>

  <joint name="base_to_pan_joint" type="fixed">
    <origin xyz="0 0 0.021" rpy="0 0 0"/>
    <parent link="base_link"/>
    <child link="pan_link"/>
  </joint>

  <link name="pan_link">
    <visual>
      <geometry>
        <mesh filename="package://holoruch_pantilt_description/meshes/AX-12A.stl" />
      </geometry>
    </visual>
    <collision>
      <geometry>
        <mesh filename="package://holoruch_pantilt_description/meshes/AX-12A_convex.stl" />
      </geometry>
    </collision>
    <inertial>
      <origin rpy="0 0 0" xyz="0 0 0"/>
      <mass value="0.055"/>
      <inertia ixx="1" ixy="0" ixz="0" iyy="1" iyz="0" izz="1"/>
    </inertial>
  </link>

  <joint name="pan_joint" type="revolute">
    <origin xyz="0 0 0.06" rpy="0 0 0"/>
    <parent link="pan_link"/>
    <child link="tilt_link"/>
    <limit lower="-1.57079" upper="1.57079" effort="1.0" velocity="1.0" />
    <axis xyz="0 0 1" />
  </joint>

  <link name="tilt_link">
    <visual>
      <origin rpy="1.57079 0 1.57079" xyz="0 0 0"/>
      <geometry>
        <mesh filename="package://holoruch_pantilt_description/meshes/AX-12A.stl" />
      </geometry>
    </visual>
    <collision>
      <origin rpy="1.57079 0 1.57079" xyz="0 0 0"/>
      <geometry>
        <mesh filename="package://holoruch_pantilt_description/meshes/AX-12A_convex.stl" />
      </geometry>
    </collision>
    <inertial>
      <origin rpy="0 0 0" xyz="0 0 0"/>
      <mass value="0.055"/>
      <inertia ixx="1" ixy="0" ixz="0" iyy="1" iyz="0" izz="1"/>
    </inertial>
  </link>

  <joint name="tilt_joint" type="revolute">
    <origin xyz="0 0.0 0.035" rpy="0 0 0"/>
    <parent link="tilt_link"/>
    <child link="camera_link"/>
    <limit lower="-0.3" upper="1.57079" effort="1.0" velocity="1.0" />
    <axis xyz="1 0 0" />
  </joint>

  <link name="camera_link">
    <visual>
      <origin rpy="0 0 0" xyz="0 0.04 0"/>
      <geometry>
        <box size="0.09 0.03 0.04" />
      </geometry>
    </visual>
    <collision>
      <origin rpy="0 0 0" xyz="0 0.04 0"/>
      <geometry>
        <box size="0.09 0.03 0.04" />
      </geometry>
    </collision>
    <inertial>
      <origin rpy="0 0 0" xyz="0 0 0"/>
      <mass value="0.08"/>
      <inertia ixx="1" ixy="0" ixz="0" iyy="1" iyz="0" izz="1"/>
    </inertial>
  </link>
</robot>
