<sdf version='1.5'>
  <model name='holoruch_pantilt'>
    <link name='base_link'>
      <pose>0 0 0 0 -0 0</pose>
      <inertial>
        <pose>0 0 0.00745161 0 -0 0</pose>
        <mass>0.155</mass>
        <inertia>
          <ixx>2.00002</ixx>
          <ixy>0</ixy>
          <ixz>0</ixz>
          <iyy>2.00002</iyy>
          <iyz>0</iyz>
          <izz>2</izz>
        </inertia>
      </inertial>
      <collision name='base_link_collision'>
        <pose>0 0 0 0 -0 0</pose>
        <geometry>
          <box>
            <size>0.15 0.13 0.01</size>
          </box>
        </geometry>
      </collision>
      <collision name='base_link_collision_base_link_1'>
        <pose>0 0 0.021 0 -0 0</pose>
        <geometry>
          <mesh>
            <scale>1 1 1</scale>
            <uri>model://holoruch_pantilt_description/meshes/AX-12A_convex.stl</uri>
          </mesh>
        </geometry>
      </collision>
      <visual name='base_link_visual'>
        <pose>0 0 0 0 -0 0</pose>
        <geometry>
          <box>
            <size>0.15 0.13 0.01</size>
          </box>
        </geometry>
      </visual>
      <visual name='base_link_visual_base_link_1'>
        <pose>0 0 0.021 0 -0 0</pose>
        <geometry>
          <mesh>
            <scale>1 1 1</scale>
            <uri>model://holoruch_pantilt_description/meshes/AX-12A.stl</uri>
          </mesh>
        </geometry>
      </visual>
    </link>
    <link name='tilt_link'>
      <pose>0 0 0.081 0 -0 0</pose>
      <inertial>
        <pose>0 0 0 1.57079 -0 1.57079</pose>
        <mass>0.055</mass>
        <inertia>
          <ixx>1</ixx>
          <ixy>0</ixy>
          <ixz>0</ixz>
          <iyy>1</iyy>
          <iyz>0</iyz>
          <izz>1</izz>
        </inertia>
      </inertial>
      <collision name='tilt_link_collision'>
        <pose>0 0 0 1.57079 -0 1.57079</pose>
        <geometry>
          <mesh>
            <scale>1 1 1</scale>
            <uri>model://holoruch_pantilt_description/meshes/AX-12A_convex.stl</uri>
          </mesh>
        </geometry>
      </collision>
      <visual name='tilt_link_visual'>
        <pose>0 0 0 1.57079 -0 1.57079</pose>
        <geometry>
          <mesh>
            <scale>1 1 1</scale>
            <uri>model://holoruch_pantilt_description/meshes/AX-12A.stl</uri>
          </mesh>
        </geometry>
      </visual>
    </link>
    <joint name='pan_joint' type='revolute'>
      <child>tilt_link</child>
      <parent>base_link</parent>
      <axis>
        <xyz>0 0 1</xyz>
        <limit>
          <lower>-1.57079</lower>
          <upper>1.57079</upper>
          <effort>1</effort>
          <velocity>1</velocity>
        </limit>
        <dynamics>
          <spring_reference>0</spring_reference>
          <spring_stiffness>0</spring_stiffness>
        </dynamics>
        <use_parent_model_frame>1</use_parent_model_frame>
      </axis>
    </joint>
    <link name='camera_link'>
      <pose>0 0 0.116 0 -0 0</pose>
      <inertial>
        <pose>0 0.04 0 0 -0 0</pose>
        <mass>0.08</mass>
        <inertia>
          <ixx>1</ixx>
          <ixy>0</ixy>
          <ixz>0</ixz>
          <iyy>1</iyy>
          <iyz>0</iyz>
          <izz>1</izz>
        </inertia>
      </inertial>
      <collision name='camera_link_collision'>
        <pose>0 0.04 0 0 -0 0</pose>
        <geometry>
          <box>
            <size>0.09 0.03 0.04</size>
          </box>
        </geometry>
      </collision>
      <visual name='camera_link_visual'>
        <pose>0 0.04 0 0 -0 0</pose>
        <geometry>
          <box>
            <size>0.09 0.03 0.04</size>
          </box>
        </geometry>
      </visual>
      <sensor name="camera_sensor" type="camera">
        <always_on>1</always_on>
        <visualize>0</visualize>
        <pose>
          0 0 0.116
          3.14159 3.14159 -1.5708
        </pose>
        <update_rate>30</update_rate>
        <camera>
          <horizontal_fov>1.0</horizontal_fov>
          <image>
            <width>640</width>
            <height>480</height>
            <format>R8G8B8</format>
          </image>
          <clip>
            <near>0.0100000</near>
            <far>100.000000</far>
          </clip>
        </camera>
        <plugin name="camera_sensor_ros" filename="libgazebo_ros_camera.so">
          <alwaysOn>true</alwaysOn>
          <cameraName>/simcam</cameraName>
          <imageTopicName>image_raw</imageTopicName>
          <cameraInfoTopicName>camera_info</cameraInfoTopicName>
          <frameName>sim_cam</frameName>
        </plugin>
      </sensor>
    </link>
    <joint name='tilt_joint' type='revolute'>
      <child>camera_link</child>
      <parent>tilt_link</parent>
      <axis>
        <xyz>1 0 0</xyz>
        <limit>
          <lower>-0.3</lower>
          <upper>1.57079</upper>
          <effort>1</effort>
          <velocity>1</velocity>
        </limit>
        <dynamics>
          <spring_reference>0</spring_reference>
          <spring_stiffness>0</spring_stiffness>
        </dynamics>
        <use_parent_model_frame>1</use_parent_model_frame>
      </axis>
    </joint>
    <plugin name="joint_pos_control" filename="libRobotJointPositionControlPlugin.so">
      <robotNamespace>/pantilt</robotNamespace>
      <jointsReadTopic>get_joint_positions</jointsReadTopic>
      <jointsWriteTopic>set_joint_positions</jointsWriteTopic>
    </plugin>
  </model>
</sdf>
